<?xml version="1.0"?>
<robot xmlns:xacro="http://www.ros.org/wiki/xacro" name="firefighter">

  <xacro:property name="width" value=".2"/>


  <!-- 简洁惯性块模板，默认加至每个 link -->
  <xacro:macro name="default_inertial" params="mass">
    <inertial>
      <mass value="${mass}"/>
      <inertia ixx="0.01" ixy="0.0" ixz="0.0" iyy="0.01" iyz="0.0" izz="0.01"/>
    </inertial>
  </xacro:macro>

  <link name="base">
    <xacro:default_inertial mass="0.8"/>
    <visual>
      <geometry>
        <mesh filename="base.dae"/>
      </geometry>
      <origin xyz="0 0 0" rpy="0 0 1.5708"/>
    </visual>
    <collision>
      <geometry>
        <mesh filename="base.dae"/>
      </geometry>
      <origin xyz="0 0 0" rpy="0 0 1.5708"/>
    </collision>
  </link>

  <!-- 其余 link1 ~ gripper_right3 的 inertial 默认 mass = 0.3 -->
  <xacro:macro name="link_with_mesh" params="name file xyz rpy">
    <link name="${name}">
      <xacro:default_inertial mass="0.3"/>
      <visual>
        <geometry>
          <mesh filename="${file}"/>
        </geometry>
        <origin xyz="${xyz}" rpy="${rpy}"/>
      </visual>
      <collision>
        <geometry>
          <mesh filename="${file}"/>
        </geometry>
        <origin xyz="${xyz}" rpy="${rpy}"/>
      </collision>
    </link>
  </xacro:macro>

  <xacro:link_with_mesh name="link1" file="link1.dae" xyz="0 0 -0.078" rpy="0 0 1.5708"/>
  <xacro:link_with_mesh name="link2" file="link2.dae" xyz="0 0 -0.04" rpy="0 1.5708 0"/>
  <xacro:link_with_mesh name="link3" file="link3.dae" xyz="0 0 0.039" rpy="1.5708 1.5708 1.5708"/>
  <xacro:link_with_mesh name="link4" file="link4.dae" xyz="0 -0.0024 -0.05" rpy="1.5708 1.5708 0"/>
  <xacro:link_with_mesh name="link5" file="link5.dae" xyz="0 0 -0.05" rpy="0 0 -1.5708"/>
  <xacro:link_with_mesh name="link6" file="link6.dae" xyz="0 0 -0.0115" rpy="1.5708 1.5708 0"/>

  <!-- gripper links -->
  <xacro:link_with_mesh name="gripper_base" file="gripper_base.dae" xyz="-0.02 0.012 -0.018" rpy="0 0 1.5708"/>
  <xacro:link_with_mesh name="gripper_left1" file="gripper_left1.dae" xyz="0.036 -0.052 0.0" rpy="0 0 1.5708"/>
  <xacro:link_with_mesh name="gripper_left2" file="gripper_left2.dae" xyz="0.03 0.024 -0.018" rpy="0 0 1.5708"/>
  <xacro:link_with_mesh name="gripper_left3" file="gripper_left3.dae" xyz="0.034 0.0 -0.012" rpy="0 3.14159 -1.5708"/>
  <xacro:link_with_mesh name="gripper_right1" file="gripper_right1.dae" xyz="-0.072 -0.05 0.0" rpy="0 0 1.5708"/>
  <xacro:link_with_mesh name="gripper_right2" file="gripper_right2.dae" xyz="-0.066 0.023 -0.018" rpy="0 0 1.5708"/>
  <xacro:link_with_mesh name="gripper_right3" file="gripper_right3.dae" xyz="0 0 -0.012" rpy="0 3.14159 -1.5708"/>

  <!-- joints with姿态修正 -->
  <joint name="joint2_to_joint1" type="revolute">
    <axis xyz="0 0 1"/>
    <limit effort="1000.0" lower="-2.93" upper="2.93" velocity="0"/>
    <parent link="base"/>
    <child link="link1"/>
    <origin xyz="0 0 0.173" rpy="0 0 0"/>
  </joint>

  <joint name="joint3_to_joint2" type="revolute">
    <axis xyz="0 0 1"/>
    <limit effort="1000.0" lower="-2.35" upper="2.35" velocity="0"/>
    <parent link="link1"/>
    <child link="link2"/>
    <origin xyz="0 -0.086 0" rpy="1.5708 0 0"/>
  </joint>

  <joint name="joint4_to_joint3" type="revolute">
    <axis xyz="0 0 1"/>
    <limit effort="1000.0" lower="-2.53" upper="2.53" velocity="0"/>
    <parent link="link2"/>
    <child link="link3"/>
    <origin xyz="0.13635 0 -0.086" rpy="0 0 1.5708"/>
  </joint>

  <joint name="joint5_to_joint4" type="revolute">
    <axis xyz="0 0 1"/>
    <limit effort="1000.0" lower="-2.58" upper="2.58" velocity="0"/>
    <parent link="link3"/>
    <child link="link4"/>
    <origin xyz="0.1195 0 0.082" rpy="0 0 1.5708"/>
  </joint>

  <joint name="joint6_to_joint5" type="revolute">
    <axis xyz="0 0 1"/>
    <limit effort="1000.0" lower="-2.93" upper="2.93" velocity="0"/>
    <parent link="link4"/>
    <child link="link5"/>
    <origin xyz="0 -0.09415 0.0" rpy="0 0 0"/>
  </joint>

  <joint name="joint6output_to_joint6" type="revolute">
    <axis xyz="0 0 1"/>
    <limit effort="1000.0" lower="-3.14" upper="3.14" velocity="0"/>
    <parent link="link5"/>
    <child link="link6"/>
    <origin xyz="0 0.055 0.0" rpy="0 0 0"/>
  </joint>

  <joint name="joint6output_to_gripper_base" type="fixed">
    <parent link="link6"/>
    <child link="gripper_base"/>
    <origin xyz="0 0 0.042" rpy="0 0 0"/>
  </joint>

</robot>
